Workbook

Sheet Dashboard
A1: 75-Day SDE Plan
A2: Mon 28 Sep 2026 → Fri 11 Dec 2026 · tick ✓ in the Tracker sheet; everything here updates
A4: Overall progress (tasks) | B4: =SUM(Tracker!P2:P76)/SUM(Tracker!Q2:Q76)
A5: Days completed | B5: =COUNTIF(Tracker!S2:S76,"Completed")
A6: Days partial | B6: =COUNTIF(Tracker!S2:S76,"Partial")
A7: Days missed | B7: =COUNTIF(Tracker!S2:S76,"Missed")
A8: Today is plan day | B8: =IFERROR(MATCH(TODAY(),Tracker!B2:B76,0),"-")
A9: LeetCode solved (of 225) | B9: =COUNTIF(LeetCode!G2:G226,"Yes")
A10: LeetCode marked ↻ revisit | B10: =COUNTIF(LeetCode!H2:H226,"↻")
A11: HLD reads done | B11: =COUNTIF(Tracker!H2:H76,"✓")
A12: LLD builds done | B12: =COUNTIF(Tracker!I2:I76,"✓")
A13: Cloud labs done | B13: =COUNTIF(Tracker!J2:J76,"✓")
A14: Walk / exercise days | B14: =COUNTIF(Tracker!K2:K76,"✓")
A15: Water goal days (2.5 L+) | B15: =COUNTIF(Tracker!L2:L76,">=2.5")
A17: Phase | B17: Days | C17: Progress | D17: Completed days
A18: 1 · Foundations | B18: 1–25 | C18: =SUM(Tracker!P2:P26)/SUM(Tracker!Q2:Q26) | D18: =COUNTIF(Tracker!S2:S26,"Completed")
A19: 2 · Build and apply | B19: 26–50 | C19: =SUM(Tracker!P27:P51)/SUM(Tracker!Q27:Q51) | D19: =COUNTIF(Tracker!S27:S51,"Completed")
A20: 3 · Azure and interview mode | B20: 51–75 | C20: =SUM(Tracker!P52:P76)/SUM(Tracker!Q52:Q76) | D20: =COUNTIF(Tracker!S52:S76,"Completed")

Sheet Tracker
A1: Day | B1: Date | C1: Type | D1: Theme | E1: LC 1 | F1: LC 2 | G1: LC 3 | H1: HLD | I1: LLD | J1: Cloud | K1: Walk | L1: Water (L) | M1: Food | N1: Chill | O1: Sleep | P1: Done | Q1: Of | R1: % | S1: Status | T1: Notes
A2: 1 | B2: 46293 | C2: Office day | D2: How the web works | P2: =COUNTIF(E2:K2,"✓")+COUNTIF(M2:O2,"✓")+IF(N(L2)>=2.5,1,0) | Q2: 11 | R2: =P2/Q2 | S2: =IF(P2>=Q2,"Completed",IF(B2=TODAY(),"Today",IF(P2>0,"Partial",IF(B2>TODAY(),"Upcoming","Missed"))))
A3: 2 | B3: 46294 | C3: Office day | D3: Scaling a server | P3: =COUNTIF(E3:K3,"✓")+COUNTIF(M3:O3,"✓")+IF(N(L3)>=2.5,1,0) | Q3: 11 | R3: =P3/Q3 | S3: =IF(P3>=Q3,"Completed",IF(B3=TODAY(),"Today",IF(P3>0,"Partial",IF(B3>TODAY(),"Upcoming","Missed"))))
A4: 3 | B4: 46295 | C4: Office day | D4: Load balancing | P4: =COUNTIF(E4:K4,"✓")+COUNTIF(M4:O4,"✓")+IF(N(L4)>=2.5,1,0) | Q4: 11 | R4: =P4/Q4 | S4: =IF(P4>=Q4,"Completed",IF(B4=TODAY(),"Today",IF(P4>0,"Partial",IF(B4>TODAY(),"Upcoming","Missed"))))
A5: 4 | B5: 46296 | C5: Office day | D5: Stateless services | P5: =COUNTIF(E5:K5,"✓")+COUNTIF(M5:O5,"✓")+IF(N(L5)>=2.5,1,0) | Q5: 11 | R5: =P5/Q5 | S5: =IF(P5>=Q5,"Completed",IF(B5=TODAY(),"Today",IF(P5>0,"Partial",IF(B5>TODAY(),"Upcoming","Missed"))))
A6: 5 | B6: 46297 | C6: Light Friday | D6: APIs | P6: =COUNTIF(E6:K6,"✓")+COUNTIF(M6:O6,"✓")+IF(N(L6)>=2.5,1,0) | Q6: 11 | R6: =P6/Q6 | S6: =IF(P6>=Q6,"Completed",IF(B6=TODAY(),"Today",IF(P6>0,"Partial",IF(B6>TODAY(),"Upcoming","Missed"))))
A7: 6 | B7: 46298 | C7: Build Saturday | D7: Build: 3-tier app | P7: =COUNTIF(E7:K7,"✓")+COUNTIF(M7:O7,"✓")+IF(N(L7)>=2.5,1,0) | Q7: 11 | R7: =P7/Q7 | S7: =IF(P7>=Q7,"Completed",IF(B7=TODAY(),"Today",IF(P7>0,"Partial",IF(B7>TODAY(),"Upcoming","Missed"))))
A8: 7 | B8: 46299 | C8: Review Sunday | D8: Review week 1 | P8: =COUNTIF(E8:K8,"✓")+COUNTIF(M8:O8,"✓")+IF(N(L8)>=2.5,1,0) | Q8: 11 | R8: =P8/Q8 | S8: =IF(P8>=Q8,"Completed",IF(B8=TODAY(),"Today",IF(P8>0,"Partial",IF(B8>TODAY(),"Upcoming","Missed"))))
A9: 8 | B9: 46300 | C9: Office day | D9: Databases 101 | P9: =COUNTIF(E9:K9,"✓")+COUNTIF(M9:O9,"✓")+IF(N(L9)>=2.5,1,0) | Q9: 11 | R9: =P9/Q9 | S9: =IF(P9>=Q9,"Completed",IF(B9=TODAY(),"Today",IF(P9>0,"Partial",IF(B9>TODAY(),"Upcoming","Missed"))))
A10: 9 | B10: 46301 | C10: Office day | D10: Indexing | P10: =COUNTIF(E10:K10,"✓")+COUNTIF(M10:O10,"✓")+IF(N(L10)>=2.5,1,0) | Q10: 11 | R10: =P10/Q10 | S10: =IF(P10>=Q10,"Completed",IF(B10=TODAY(),"Today",IF(P10>0,"Partial",IF(B10>TODAY(),"Upcoming","Missed"))))
A11: 10 | B11: 46302 | C11: Office day | D11: Replication | P11: =COUNTIF(E11:K11,"✓")+COUNTIF(M11:O11,"✓")+IF(N(L11)>=2.5,1,0) | Q11: 11 | R11: =P11/Q11 | S11: =IF(P11>=Q11,"Completed",IF(B11=TODAY(),"Today",IF(P11>0,"Partial",IF(B11>TODAY(),"Upcoming","Missed"))))
A12: 11 | B12: 46303 | C12: Office day | D12: Sharding | P12: =COUNTIF(E12:K12,"✓")+COUNTIF(M12:O12,"✓")+IF(N(L12)>=2.5,1,0) | Q12: 11 | R12: =P12/Q12 | S12: =IF(P12>=Q12,"Completed",IF(B12=TODAY(),"Today",IF(P12>0,"Partial",IF(B12>TODAY(),"Upcoming","Missed"))))
A13: 12 | B13: 46304 | C13: Light Friday | D13: Transactions | P13: =COUNTIF(E13:K13,"✓")+COUNTIF(M13:O13,"✓")+IF(N(L13)>=2.5,1,0) | Q13: 11 | R13: =P13/Q13 | S13: =IF(P13>=Q13,"Completed",IF(B13=TODAY(),"Today",IF(P13>0,"Partial",IF(B13>TODAY(),"Upcoming","Missed"))))
... A76: 75 | B76: 46367 | C76: Light Friday | D76: Day 75: finish line | P76: =COUNTIF(E76:K76,"✓")+COUNTIF(M76:O76,"✓")+IF(N(L76)>=2.5,1,0) | Q76: 11 | R76: =P76/Q76 | S76: =IF(P76>=Q76,"Completed",IF(B76=TODAY(),"Today",IF(P76>0,"Partial",IF(B76>TODAY(),"Upcoming","Missed"))))

Sheet Plan
A1: Day | B1: Date | C1: Weekday | D1: Type | E1: Phase | F1: Week | G1: Theme | H1: DSA pattern | I1: Approach | J1: LeetCode 1 | K1: Diff | L1: LeetCode 2 | M1: Diff | N1: LeetCode 3 | O1: Diff | P1: HLD read (lunch) | Q1: HLD key points | R1: LLD in C# (9 pm) | S1: Cloud lab (9:30 pm) | T1: Checkpoint pass criteria
A2: 1 | B2: 46293 | C2: Mon | D2: Office day | E2: 1 | F2: 1 | G2: How the web works | H2: Arrays & hashing | I2: Trade memory for time: a HashMap / HashSet turns an O(n^2) scan into O(n). | J2: Two Sum | K2: Easy | L2: Contains Duplicate | M2: Easy | N2: Valid Anagram | O2: Easy | P2: What happens when you type a URL: DNS, TCP, HTTP | Q2: • DNS resolves the name, TCP (+TLS) opens the connection, HTTP carries the request • Browser cache → OS → resolver → root/TLD/authoritative servers • Where latency is spent: DNS, handshake, server time, download | R2: Classes, objects and encapsulation in C# | S2: AWS: AWS regions and AZs; free-tier account + billing alarm
A3: 2 | B3: 46294 | C3: Tue | D3: Office day | E3: 1 | F3: 1 | G3: Scaling a server | H3: Arrays & hashing | I3: Trade memory for time: a HashMap / HashSet turns an O(n^2) scan into O(n). | J3: Group Anagrams | K3: Medium | L3: Top K Frequent Elements | M3: Medium | N3: Product of Array Except Self | O3: Medium | P3: Vertical vs horizontal scaling | Q3: • Vertical = bigger machine: simple, has a ceiling and a single point of failure • Horizontal = more machines: needs a load balancer and stateless app servers • Scale reads with replicas and caches before sharding writes | R3: Inheritance vs composition | S3: AWS: IAM: users, groups, roles, policies, MFA
A4: 3 | B4: 46295 | C4: Wed | D4: Office day | E4: 1 | F4: 1 | G4: Load balancing | H4: Arrays & hashing | I4: Trade memory for time: a HashMap / HashSet turns an O(n^2) scan into O(n). | J4: Valid Sudoku | K4: Medium | L4: Longest Consecutive Sequence | M4: Medium | N4: Majority Element | O4: Easy | P4: Load balancers: L4 vs L7, round robin, least connections | Q4: • L4 balances TCP connections; L7 routes by path, header or cookie • Round robin vs least connections vs IP hash, and when each wins • Health checks remove bad nodes; the LB itself needs redundancy | R4: Polymorphism and interfaces: an ILoadBalancingStrategy | S4: AWS: EC2: launch an instance, security groups, SSH
A5: 4 | B5: 46296 | C5: Thu | D5: Office day | E5: 1 | F5: 1 | G5: Stateless services | H5: Two pointers | I5: Sorted input or a palindrome? Move two indices toward each other instead of nesting loops. | J5: Valid Palindrome | K5: Easy | L5: Two Sum II - Input Array Is Sorted | M5: Medium | N5: 3Sum | O5: Medium | P5: Stateless servers, sticky sessions, session stores | Q5: • Keep session state out of app servers so any server can take any request • Sticky sessions are a workaround with uneven load and lost sessions • Session stores: Redis or a DB with a TTL; JWT moves state to the client | R5: SOLID part 1: Single Responsibility, Open/Closed | S5: AWS: ALB + Auto Scaling Group
A6: 5 | B6: 46297 | C6: Fri | D6: Light Friday | E6: 1 | F6: 1 | G6: APIs | H6: Two pointers | I6: Sorted input or a palindrome? Move two indices toward each other instead of nesting loops. | J6: Container With Most Water | K6: Medium | L6: Remove Duplicates from Sorted Array | M6: Easy | N6: Move Zeroes | O6: Easy | P6: REST API design, status codes, idempotency | Q6: • Resources as nouns, HTTP verbs as actions, correct status codes (201, 400, 404, 409, 429) • Idempotency: PUT/DELETE are, POST is not unless you add an idempotency key • Versioning, pagination and consistent error bodies | R6: SOLID part 2: Liskov, Interface Segregation, Dependency Inversion | S6: AWS: S3: buckets, storage classes, static website
A7: 6 | B7: 46298 | C7: Sat | D7: Build Saturday | E7: 1 | F7: 1 | G7: Build: 3-tier app | H7: Two pointers | I7: Sorted input or a palindrome? Move two indices toward each other instead of nesting loops. | J7: Trapping Rain Water | K7: Hard | L7: Merge Sorted Array | M7: Easy | N7: Reverse String | O7: Easy | P7: Draw a 3-tier app: LB → app servers → DB | Q7: • Tier 1 LB, tier 2 stateless app servers, tier 3 database • Where each tier fails and how it recovers • What changes at 10x traffic | R7: Refactor a notification sender using SOLID | S7: AWS: Static site on S3 + EC2 app behind an ALB (terminate after!)
A8: 7 | B8: 46299 | C8: Sun | D8: Review Sunday | E8: 1 | F8: 1 | G8: Review week 1 | H8: Sliding window | I8: Grow the right edge, shrink the left while the window breaks the rule; track the best window. | J8: Best Time to Buy and Sell Stock | K8: Easy | L8: Longest Substring Without Repeating Characters | M8: Medium | N8: Longest Repeating Character Replacement | O8: Medium | P8: Revise week 1 notes on one page | Q8: • One page: the web request path, scaling, LB, stateless, REST • Say each concept in two sentences without notes • List 3 weak spots for next week | R8: Recap: 4 OOP pillars + SOLID in your own words | S8: AWS: Delete leftover resources, check billing
A9: 8 | B9: 46300 | C9: Mon | D9: Office day | E9: 1 | F9: 2 | G9: Databases 101 | H9: Sliding window | I9: Grow the right edge, shrink the left while the window breaks the rule; track the best window. | J9: Permutation in String | K9: Medium | L9: Minimum Window Substring | M9: Hard | N9: Maximum Average Subarray I | O9: Easy | P9: SQL vs NoSQL and when to pick each | Q9: • SQL: schema, joins, ACID; NoSQL: flexible schema, horizontal scale • Pick by access pattern, consistency need and scale • Key-value, document, wide-column and graph stores, with one example each | R9: Singleton pattern (thread-safe, for a DB connection) | S9: AWS: RDS: launch Postgres, connect from your laptop
A10: 9 | B10: 46301 | C10: Tue | D10: Office day | E10: 1 | F10: 2 | G10: Indexing | H10: Sliding window | I10: Grow the right edge, shrink the left while the window breaks the rule; track the best window. | J10: Sliding Window Maximum | K10: Hard | L10: Minimum Size Subarray Sum | M10: Medium | N10: Max Consecutive Ones III | O10: Medium | P10: Indexes, B-trees, why queries get slow | Q10: • An index is a sorted structure (B-tree) that trades write speed for read speed • Composite index column order matters (leftmost prefix) • Read EXPLAIN plans: full scan vs index seek | R10: Factory pattern | S10: AWS: RDS backups, snapshots, Multi-AZ
A11: 10 | B11: 46302 | C11: Wed | D11: Office day | E11: 1 | F11: 2 | G11: Replication | H11: Stack | I11: Anything 'nearest greater/smaller' or matching pairs is a monotonic or plain stack. | J11: Valid Parentheses | K11: Easy | L11: Min Stack | M11: Medium | N11: Evaluate Reverse Polish Notation | O11: Medium | P11: Primary-replica replication, read replicas, lag | Q11: • Primary takes writes, replicas serve reads • Async replication means lag: read-your-own-writes issues • Failover promotes a replica; watch for split brain | R11: Builder pattern | S11: AWS: RDS read replicas; DynamoDB intro
A12: 11 | B12: 46303 | C12: Thu | D12: Office day | E12: 1 | F12: 2 | G12: Sharding | H12: Stack | I12: Anything 'nearest greater/smaller' or matching pairs is a monotonic or plain stack. | J12: Generate Parentheses | K12: Medium | L12: Daily Temperatures | M12: Medium | N12: Car Fleet | O12: Medium | P12: Partitioning, shard keys, hot spots | Q12: • Shard by a key that spreads load evenly • Hot spots come from celebrity keys or time-ordered keys • Cross-shard queries and rebalancing are the real cost | R12: Strategy pattern (a shard-key strategy) | S12: AWS: DynamoDB partition keys and GSIs
A13: 12 | B13: 46304 | C13: Fri | D13: Light Friday | E13: 1 | F13: 2 | G13: Transactions | H13: Stack | I13: Anything 'nearest greater/smaller' or matching pairs is a monotonic or plain stack. | J13: Next Greater Element I | K13: Easy | L13: Implement Queue using Stacks | M13: Easy | N13: Simplify Path | O13: Medium | P13: ACID and isolation levels | Q13: • ACID: atomicity, consistency, isolation, durability • Isolation levels vs anomalies: dirty read, non-repeatable read, phantom • When to use SERIALIZABLE and what it costs | R13: Repository pattern in C# | S13: AWS: IAM roles for EC2 to read S3 without keys
... A25: 24 | B25: 46316 | C25: Wed | D25: Office day | E25: 1 | F25: 4 | G25: Delivery guarantees | H25: Binary search | I25: Search the answer space, not just arrays: find the first value where a yes/no check flips. | J25: Find Peak Element | K25: Medium | L25: Single Element in a Sorted Array | M25: Medium | N25: Capacity To Ship Packages Within D Days | O25: Medium | P25: At-least-once, exactly-once, idempotency, dead-letter queues | Q25: • At-least-once delivery means duplicates: make consumers idempotent • Exactly-once is expensive; dedupe keys are usually enough • Dead-letter queues catch poison messages; visibility timeout controls retries | R25: Command pattern for retryable jobs | S25: AWS: SQS dead-letter queue, visibility timeout
A26: 25 | B26: 46317 | C26: Thu | D26: Office day | E26: 1 | F26: 4 | G26: Phase 1 checkpoint | H26: Arrays & matrix | I26: In-place tricks: reverse segments, swap by index, use the first row/column as markers. | J26: Sort Colors | K26: Medium | L26: Rotate Array | M26: Medium | N26: Rotate Image | O26: Medium | P26: Design a basic notification system | Q26: • Channels (email, SMS, push) behind one interface • Queue per channel, retries with backoff, user preferences • Checkpoint: explain it in 10 minutes | R26: Notification service LLD: Strategy for channels + Observer | S26: AWS: AWS Cloud Practitioner practice test | T26: • Solve 3 new mediums from Phase 1 patterns in 90 minutes • Explain a 3-tier app, caching and queues in 10 minutes without notes • Code a SOLID notification sender in C# with tests • AWS Cloud Practitioner practice test: 70%+
A27: 26 | B27: 46318 | C27: Fri | D27: Light Friday | E27: 2 | F27: 4 | G27: Serverless | H27: Trees | I27: Recursion returns what the parent needs; DFS for depth/paths, BFS (queue) for levels. | J27: Invert Binary Tree | K27: Easy | L27: Maximum Depth of Binary Tree | M27: Easy | N27: Same Tree | O27: Easy | P27: Serverless vs servers: trade-offs | Q27: • Serverless: no servers to manage, pay per call, scales to zero • Cold starts, time limits and vendor lock-in • Good for spiky, event-driven work | R27: Template Method pattern | S27: AWS: Lambda: deploy a .NET function
A28: 27 | B28: 46319 | C28: Sat | D28: Build Saturday | E28: 2 | F28: 4 | G28: Build: image pipeline | H28: Trees | I28: Recursion returns what the parent needs; DFS for depth/paths, BFS (queue) for levels. | J28: Diameter of Binary Tree | K28: Easy | L28: Balanced Binary Tree | M28: Easy | N28: Subtree of Another Tree | O28: Easy | P28: Design an image upload + thumbnail pipeline | Q28: • Upload to object storage, event triggers processing • Thumbnails generated asynchronously • Store metadata in a DB; serve images through a CDN | R28: Chain of Responsibility for processing steps | S28: AWS: S3 upload triggers a Lambda
A29: 28 | B29: 46320 | C29: Sun | D29: Review Sunday | E29: 2 | F29: 4 | G29: Review week 4 | H29: Trees | I29: Recursion returns what the parent needs; DFS for depth/paths, BFS (queue) for levels. | J29: Symmetric Tree | K29: Easy | L29: Path Sum | M29: Easy | N29: Binary Tree Paths | O29: Easy | P29: Revise all of Phase 1 on one page | Q29: • Revise all of Phase 1 on one page • Re-draw 3-tier app, cache, queue and rate limiter • Pick the 3 weakest topics | R29: Recap: all patterns so far, one line each | S29: AWS: Clean up, check billing
A30: 29 | B30: 46321 | C30: Mon | D30: Office day | E30: 2 | F30: 5 | G30: API gateway | H30: Trees | I30: Recursion returns what the parent needs; DFS for depth/paths, BFS (queue) for levels. | J30: Binary Tree Level Order Traversal | K30: Medium | L30: Binary Tree Right Side View | M30: Medium | N30: Average of Levels in Binary Tree | O30: Easy | P30: API gateway, BFF, auth at the edge | Q30: • API gateway: routing, auth, rate limiting, TLS in one place • BFF: one backend per client type (web, mobile) • Auth at the edge vs in each service | R30: Facade pattern | S30: AWS: API Gateway + Lambda REST API
A31: 30 | B31: 46322 | C31: Tue | D31: Office day | E31: 2 | F31: 5 | G31: Microservices | H31: Trees | I31: Recursion returns what the parent needs; DFS for depth/paths, BFS (queue) for levels. | J31: Lowest Common Ancestor of a Binary Search Tree | K31: Medium | L31: Validate Binary Search Tree | M31: Medium | N31: Kth Smallest Element in a BST | O31: Medium | P31: Monolith vs microservices, sync vs async calls | Q31: • Monolith first; split by business capability • Sync (REST/gRPC) couples availability; async decouples • Data ownership: one DB per service | R31: Adapter pattern | S31: AWS: Docker image → ECR
A32: 31 | B32: 46323 | C32: Wed | D32: Office day | E32: 2 | F32: 5 | G32: Containers | H32: Trees | I32: Recursion returns what the parent needs; DFS for depth/paths, BFS (queue) for levels. | J32: Construct Binary Tree from Preorder and Inorder Traversal | K32: Medium | L32: Count Good Nodes in Binary Tree | M32: Medium | N32: Lowest Common Ancestor of a Binary Tree | O32: Medium | P32: Service discovery and health checks | Q32: • Service discovery: registry or DNS • Liveness vs readiness health checks • Containers vs VMs | R32: Dependency injection deep dive in .NET | S32: AWS: ECS Fargate: run your container
A33: 32 | B33: 46324 | C33: Thu | D33: Office day | E33: 2 | F33: 5 | G33: Auth | H33: Trees | I33: Recursion returns what the parent needs; DFS for depth/paths, BFS (queue) for levels. | J33: Serialize and Deserialize Binary Tree | K33: Hard | L33: Delete Node in a BST | M33: Medium | N33: Convert Sorted Array to Binary Search Tree | O33: Easy | P33: Authentication vs authorization, JWT, OAuth2 | Q33: • Authentication = who you are; authorization = what you may do • JWT structure and why short expiry + refresh tokens • OAuth2 authorization code flow | R33: Design an auth module with interfaces | S33: AWS: Cognito basics
A34: 33 | B34: 46325 | C34: Fri | D34: Light Friday | E34: 2 | F34: 5 | G34: Observability | H34: Trees | I34: Recursion returns what the parent needs; DFS for depth/paths, BFS (queue) for levels. | J34: Search in a Binary Search Tree | K34: Easy | L34: Insert into a Binary Search Tree | M34: Medium | N34: Range Sum of BST | O34: Easy | P34: Logs, metrics, traces | Q34: • Logs = events, metrics = numbers over time, traces = one request across services • Correlation IDs tie them together • Alert on symptoms (latency, errors), not causes | R34: Structured logging design | S34: AWS: CloudWatch logs, metrics, alarms
A35: 34 | B35: 46326 | C35: Sat | D35: Build Saturday | E35: 2 | F35: 5 | G35: Build: URL shortener | H35: Trees | I35: Recursion returns what the parent needs; DFS for depth/paths, BFS (queue) for levels. | J35: Binary Tree Maximum Path Sum | K35: Hard | L35: Flatten Binary Tree to Linked List | M35: Medium | N35: Populating Next Right Pointers in Each Node | O35: Medium | P35: Design a URL shortener | Q35: • Requirements: shorten, redirect, custom alias, expiry • Key generation: base62 counter vs hash; collisions • Read-heavy: cache hot links, 301 vs 302 | R35: URL shortener LLD: ID generator, base62 | S35: AWS: Build it: API Gateway + Lambda + DynamoDB
A36: 35 | B36: 46327 | C36: Sun | D36: Review Sunday | E36: 2 | F36: 5 | G36: Review week 5 | H36: Heap / priority queue | I36: Top-K or 'always the smallest next' = heap; keep it size K for O(n log K). | J36: Kth Largest Element in a Stream | K36: Easy | L36: Last Stone Weight | M36: Easy | N36: Kth Largest Element in an Array | O36: Medium | P36: Revise APIs, microservices, auth | Q36: • Revise APIs, microservices and auth • Explain JWT and OAuth2 out loud • List weak spots | R36: Recap: Facade, Adapter, DI | S36: AWS: Clean up, check billing
A37: 36 | B37: 46328 | C37: Mon | D37: Office day | E37: 2 | F37: 6 | G37: Scheduling | H37: Heap / priority queue | I37: Top-K or 'always the smallest next' = heap; keep it size K for O(n log K). | J37: K Closest Points to Origin | K37: Medium | L37: Task Scheduler | M37: Medium | N37: Design Twitter | O37: Medium | P37: Job schedulers and priority queues | Q37: • Scheduler: store jobs, pick due ones, run with retries • Priority queues order work • Distributed schedulers need locking so a job runs once | R37: Parking Lot part 1: requirements + entities | S37: AWS: EventBridge scheduled rules
A38: 37 | B38: 46329 | C38: Tue | D38: Office day | E38: 2 | F38: 6 | G38: Consistent hashing | H38: Heap / priority queue | I38: Top-K or 'always the smallest next' = heap; keep it size K for O(n log K). | J38: Find Median from Data Stream | K38: Hard | L38: Reorganize String | M38: Medium | N38: Sort Characters By Frequency | O38: Medium | P38: Consistent hashing | Q38: • Hash ring: adding a node moves only nearby keys • Virtual nodes smooth out load • Used in caches, DynamoDB, Cassandra | R38: Parking Lot part 2: pricing strategy, spot allocation | S38: AWS: VPC: public/private subnets, NAT
... A50: 49 | B50: 46341 | C50: Sun | D50: Review Sunday | E50: 2 | F50: 7 | G50: Review week 7 | H50: Bit manipulation | I50: x & (x-1) drops the lowest set bit; XOR cancels pairs; shifts read bits one by one. | J50: Reverse Bits | K50: Easy | L50: Missing Number | M50: Easy | N50: Sum of Two Integers | O50: Medium | P50: Revise search, concurrency, real-time | Q50: • Revise search, concurrency and real-time • Explain locking choices out loud • List weak spots | R50: Recap: Trie, BookMyShow, Chat, Splitwise | S50: AWS: Clean up, check billing
A51: 50 | B51: 46342 | C51: Mon | D51: Office day | E51: 2 | F51: 8 | G51: Phase 2 checkpoint | H51: Dynamic programming | I51: Define dp[i] in words, write the recurrence, fix the base case, then optimise space. | J51: Climbing Stairs | K51: Easy | L51: Min Cost Climbing Stairs | M51: Easy | N51: House Robber | O51: Medium | P51: Notification system v2: retries, preferences, rate limits | Q51: • Notification v2: retries, preferences, rate limits, templates • Priorities and quiet hours • Checkpoint: whiteboard it in 25 minutes | R51: Logger framework LLD | S51: AWS: AWS Cloud Practitioner full mock | T51: • Solve 1 tree, 1 graph and 1 heap medium in 75 minutes • Whiteboard notification system v2 in 25 minutes • Implement one classic LLD (Parking Lot or Splitwise) end to end in 60 minutes • AWS Cloud Practitioner full mock: 75%+
A52: 51 | B52: 46343 | C52: Tue | D52: Office day | E52: 3 | F52: 8 | G52: Azure basics | H52: Dynamic programming | I52: Define dp[i] in words, write the recurrence, fix the base case, then optimise space. | J52: House Robber II | K52: Medium | L52: Longest Palindromic Substring | M52: Medium | N52: Palindromic Substrings | O52: Medium | P52: Estimation practice on a real system | Q52: • Estimate a real system you use (e.g. WhatsApp) end to end • QPS, storage, bandwidth, servers • Say assumptions out loud | R52: Snake and Ladder LLD | S52: Azure: Azure subscriptions, resource groups, regions (vs AWS)
A53: 52 | B53: 46344 | C53: Wed | D53: Office day | E53: 3 | F53: 8 | G53: Identity | H53: Dynamic programming | I53: Define dp[i] in words, write the recurrence, fix the base case, then optimise space. | J53: Decode Ways | K53: Medium | L53: Coin Change | M53: Medium | N53: Maximum Product Subarray | O53: Medium | P53: Design Pastebin | Q53: • Pastebin: write once, read many • Object storage for content, DB for metadata • Expiry, access control, caching | R53: Tic-Tac-Toe LLD | S53: Azure: Entra ID and RBAC (vs IAM)
A54: 53 | B54: 46345 | C54: Thu | D54: Office day | E54: 3 | F54: 8 | G54: Compute | H54: Dynamic programming | I54: Define dp[i] in words, write the recurrence, fix the base case, then optimise space. | J54: Word Break | K54: Medium | L54: Longest Increasing Subsequence | M54: Medium | N54: Partition Equal Subset Sum | O54: Medium | P54: Design a basic key-value store | Q54: • Key-value store API: get, put, delete with TTL • Partitioning + replication + consistency level • Hinted handoff and read repair (idea level) | R54: In-memory KV store with TTL | S54: Azure: Azure VMs, Scale Sets, Load Balancer (vs EC2/ASG/ELB)
A55: 54 | B55: 46346 | C55: Fri | D55: Light Friday | E55: 3 | F55: 8 | G55: Storage | H55: Dynamic programming | I55: Define dp[i] in words, write the recurrence, fix the base case, then optimise space. | J55: Fibonacci Number | K55: Easy | L55: N-th Tribonacci Number | M55: Easy | N55: Pascal's Triangle | O55: Easy | P55: Revise caching + CDN | Q55: • Revise caching strategies and CDNs • Re-draw cache-aside with invalidation • Map CloudFront → Front Door | R55: Revise LRU | S55: Azure: Blob Storage + Front Door (vs S3/CloudFront)
A56: 55 | B56: 46347 | C56: Sat | D56: Build Saturday | E56: 3 | F56: 8 | G56: Build: .NET on Azure | H56: Dynamic programming | I56: Define dp[i] in words, write the recurrence, fix the base case, then optimise space. | J56: Unique Paths | K56: Medium | L56: Longest Common Subsequence | M56: Medium | N56: Best Time to Buy and Sell Stock with Cooldown | O56: Medium | P56: Design a basic web crawler | Q56: • Web crawler: URL frontier, fetchers, parser, dedupe • Politeness per domain, robots.txt • Store content and follow links breadth-first | R56: Cache with pluggable eviction (LRU/LFU strategy) | S56: Azure: Deploy your .NET API to App Service + Azure PostgreSQL
A57: 56 | B57: 46348 | C57: Sun | D57: Review Sunday | E57: 3 | F57: 8 | G57: Review week 8 | H57: Dynamic programming | I57: Define dp[i] in words, write the recurrence, fix the base case, then optimise space. | J57: Coin Change II | K57: Medium | L57: Target Sum | M57: Medium | N57: Interleaving String | O57: Medium | P57: Revise Phase 3 so far | Q57: • Revise Phase 3 so far • Re-draw KV store and crawler • List weak spots | R57: Recap: KV store, eviction strategies | S57: Azure: Clean up Azure resources
A58: 57 | B58: 46349 | C58: Mon | D58: Office day | E58: 3 | F58: 9 | G58: Distributed rate limiting | H58: Dynamic programming | I58: Define dp[i] in words, write the recurrence, fix the base case, then optimise space. | J58: Edit Distance | K58: Medium | L58: Minimum Path Sum | M58: Medium | N58: Maximal Square | O58: Medium | P58: Rate limiter v2 with Redis | Q58: • Distributed rate limiting with Redis INCR / sliding window • Atomicity with Lua scripts • Fail open vs fail closed | R58: Add sliding window to your rate limiter | S58: Azure: Azure Cache for Redis
A59: 58 | B59: 46350 | C59: Tue | D59: Office day | E59: 3 | F59: 9 | G59: Scheduling on Azure | H59: Backtracking | I59: Choose → explore → un-choose; prune early; sort first when duplicates must be skipped. | J59: Subsets | K59: Medium | L59: Combination Sum | M59: Medium | N59: Permutations | O59: Medium | P59: Design a job scheduler | Q59: • Job scheduler: API, store, dispatcher, workers • Exactly-once-ish with leases and idempotent jobs • Retries, backoff, dead letters | R59: Task scheduler LLD: priority queue + Command | S59: Azure: Azure Functions + timer triggers (vs Lambda/EventBridge)
A60: 59 | B60: 46351 | C60: Wed | D60: Office day | E60: 3 | F60: 9 | G60: Event-driven | H60: Backtracking | I60: Choose → explore → un-choose; prune early; sort first when duplicates must be skipped. | J60: Subsets II | K60: Medium | L60: Combination Sum II | M60: Medium | N60: Palindrome Partitioning | O60: Medium | P60: Design an event-driven order system | Q60: • Order service emits events; payment, inventory and shipping react • Saga pattern for multi-step transactions • Outbox pattern to publish reliably | R60: Order management with State pattern | S60: Azure: Service Bus queues and topics (vs SQS/SNS)
A61: 60 | B61: 46352 | C61: Thu | D61: Office day | E61: 3 | F61: 9 | G61: File storage | H61: Backtracking | I61: Choose → explore → un-choose; prune early; sort first when duplicates must be skipped. | J61: Letter Combinations of a Phone Number | K61: Medium | L61: N-Queens | M61: Hard | N61: Combinations | O61: Medium | P61: Design Dropbox (basic) | Q61: • Dropbox: chunked upload, dedupe, sync • Metadata DB vs block storage • Conflict resolution across devices | R61: File system LLD with Composite pattern | S61: Azure: Storage accounts and SAS tokens
A62: 61 | B62: 46353 | C62: Fri | D62: Light Friday | E62: 3 | F62: 9 | G62: Monitoring | H62: Greedy | I62: Prove the local choice never hurts (exchange argument) before trusting it. | J62: Assign Cookies | K62: Easy | L62: Lemonade Change | M62: Easy | N62: Best Time to Buy and Sell Stock II | O62: Medium | P62: Revise estimation | Q62: • Revise estimation • Two quick estimates from memory • Check your numbers against known systems | R62: Composite pattern recap | S62: Azure: Azure Monitor + App Insights (vs CloudWatch)
...

Sheet LeetCode
A1: # | B1: Day | C1: Date | D1: Problem | E1: Difficulty | F1: Pattern | G1: Solved | H1: Revisit | I1: Notes
A2: 1 | B2: 1 | C2: 46293 | D2: Two Sum | E2: Easy | F2: Arrays & hashing | G2: =IF(Tracker!E2="✓","Yes","")
A3: 2 | B3: 1 | C3: 46293 | D3: Contains Duplicate | E3: Easy | F3: Arrays & hashing | G3: =IF(Tracker!F2="✓","Yes","")
A4: 3 | B4: 1 | C4: 46293 | D4: Valid Anagram | E4: Easy | F4: Arrays & hashing | G4: =IF(Tracker!G2="✓","Yes","")
A5: 4 | B5: 2 | C5: 46294 | D5: Group Anagrams | E5: Medium | F5: Arrays & hashing | G5: =IF(Tracker!E3="✓","Yes","")
A6: 5 | B6: 2 | C6: 46294 | D6: Top K Frequent Elements | E6: Medium | F6: Arrays & hashing | G6: =IF(Tracker!F3="✓","Yes","")
A7: 6 | B7: 2 | C7: 46294 | D7: Product of Array Except Self | E7: Medium | F7: Arrays & hashing | G7: =IF(Tracker!G3="✓","Yes","")
A8: 7 | B8: 3 | C8: 46295 | D8: Valid Sudoku | E8: Medium | F8: Arrays & hashing | G8: =IF(Tracker!E4="✓","Yes","")
A9: 8 | B9: 3 | C9: 46295 | D9: Longest Consecutive Sequence | E9: Medium | F9: Arrays & hashing | G9: =IF(Tracker!F4="✓","Yes","")
A10: 9 | B10: 3 | C10: 46295 | D10: Majority Element | E10: Easy | F10: Arrays & hashing | G10: =IF(Tracker!G4="✓","Yes","")
A11: 10 | B11: 4 | C11: 46296 | D11: Valid Palindrome | E11: Easy | F11: Two pointers | G11: =IF(Tracker!E5="✓","Yes","")
A12: 11 | B12: 4 | C12: 46296 | D12: Two Sum II - Input Array Is Sorted | E12: Medium | F12: Two pointers | G12: =IF(Tracker!F5="✓","Yes","")
A13: 12 | B13: 4 | C13: 46296 | D13: 3Sum | E13: Medium | F13: Two pointers | G13: =IF(Tracker!G5="✓","Yes","")
A14: 13 | B14: 5 | C14: 46297 | D14: Container With Most Water | E14: Medium | F14: Two pointers | G14: =IF(Tracker!E6="✓","Yes","")
A15: 14 | B15: 5 | C15: 46297 | D15: Remove Duplicates from Sorted Array | E15: Easy | F15: Two pointers | G15: =IF(Tracker!F6="✓","Yes","")
A16: 15 | B16: 5 | C16: 46297 | D16: Move Zeroes | E16: Easy | F16: Two pointers | G16: =IF(Tracker!G6="✓","Yes","")
A17: 16 | B17: 6 | C17: 46298 | D17: Trapping Rain Water | E17: Hard | F17: Two pointers | G17: =IF(Tracker!E7="✓","Yes","")
A18: 17 | B18: 6 | C18: 46298 | D18: Merge Sorted Array | E18: Easy | F18: Two pointers | G18: =IF(Tracker!F7="✓","Yes","")
A19: 18 | B19: 6 | C19: 46298 | D19: Reverse String | E19: Easy | F19: Two pointers | G19: =IF(Tracker!G7="✓","Yes","")
A20: 19 | B20: 7 | C20: 46299 | D20: Best Time to Buy and Sell Stock | E20: Easy | F20: Sliding window | G20: =IF(Tracker!E8="✓","Yes","")
A21: 20 | B21: 7 | C21: 46299 | D21: Longest Substring Without Repeating Characters | E21: Medium | F21: Sliding window | G21: =IF(Tracker!F8="✓","Yes","")
A22: 21 | B22: 7 | C22: 46299 | D22: Longest Repeating Character Replacement | E22: Medium | F22: Sliding window | G22: =IF(Tracker!G8="✓","Yes","")
A23: 22 | B23: 8 | C23: 46300 | D23: Permutation in String | E23: Medium | F23: Sliding window | G23: =IF(Tracker!E9="✓","Yes","")
A24: 23 | B24: 8 | C24: 46300 | D24: Minimum Window Substring | E24: Hard | F24: Sliding window | G24: =IF(Tracker!F9="✓","Yes","")
A25: 24 | B25: 8 | C25: 46300 | D25: Maximum Average Subarray I | E25: Easy | F25: Sliding window | G25: =IF(Tracker!G9="✓","Yes","")
A26: 25 | B26: 9 | C26: 46301 | D26: Sliding Window Maximum | E26: Hard | F26: Sliding window | G26: =IF(Tracker!E10="✓","Yes","")
A27: 26 | B27: 9 | C27: 46301 | D27: Minimum Size Subarray Sum | E27: Medium | F27: Sliding window | G27: =IF(Tracker!F10="✓","Yes","")
A28: 27 | B28: 9 | C28: 46301 | D28: Max Consecutive Ones III | E28: Medium | F28: Sliding window | G28: =IF(Tracker!G10="✓","Yes","")
A29: 28 | B29: 10 | C29: 46302 | D29: Valid Parentheses | E29: Easy | F29: Stack | G29: =IF(Tracker!E11="✓","Yes","")
A30: 29 | B30: 10 | C30: 46302 | D30: Min Stack | E30: Medium | F30: Stack | G30: =IF(Tracker!F11="✓","Yes","")
A31: 30 | B31: 10 | C31: 46302 | D31: Evaluate Reverse Polish Notation | E31: Medium | F31: Stack | G31: =IF(Tracker!G11="✓","Yes","")
A32: 31 | B32: 11 | C32: 46303 | D32: Generate Parentheses | E32: Medium | F32: Stack | G32: =IF(Tracker!E12="✓","Yes","")
A33: 32 | B33: 11 | C33: 46303 | D33: Daily Temperatures | E33: Medium | F33: Stack | G33: =IF(Tracker!F12="✓","Yes","")
A34: 33 | B34: 11 | C34: 46303 | D34: Car Fleet | E34: Medium | F34: Stack | G34: =IF(Tracker!G12="✓","Yes","")
A35: 34 | B35: 12 | C35: 46304 | D35: Next Greater Element I | E35: Easy | F35: Stack | G35: =IF(Tracker!E13="✓","Yes","")
A36: 35 | B36: 12 | C36: 46304 | D36: Implement Queue using Stacks | E36: Easy | F36: Stack | G36: =IF(Tracker!F13="✓","Yes","")
A37: 36 | B37: 12 | C37: 46304 | D37: Simplify Path | E37: Medium | F37: Stack | G37: =IF(Tracker!G13="✓","Yes","")
A38: 37 | B38: 13 | C38: 46305 | D38: Largest Rectangle in Histogram | E38: Hard | F38: Stack | G38: =IF(Tracker!E14="✓","Yes","")
A39: 38 | B39: 13 | C39: 46305 | D39: Online Stock Span | E39: Medium | F39: Stack | G39: =IF(Tracker!F14="✓","Yes","")
A40: 39 | B40: 13 | C40: 46305 | D40: Decode String | E40: Medium | F40: Stack | G40: =IF(Tracker!G14="✓","Yes","")
...

Sheet Timetable
A1: When | B1: Time | C1: What | D1: Notes
A2: Mon–Fri | B2: 7:00 | C2: Wake, 500 ml water | D2: Start the water count before the phone
A3: Mon–Fri | B3: 7:15 | C3: Walk 1 km+ or 30 min workout | D3: Outdoors if you can
A4: Mon–Fri | B4: 7:50 | C4: LeetCode #1 and #2 | D4: Fresh brain, hardest problem first; 30 min max each
A5: Mon–Fri | B5: 9:00 | C5: Breakfast, get ready | D5: Fill a 1 L bottle for the desk
A6: Mon–Fri | B6: 10:00 | C6: Office | D6: First litre done by lunch
A7: Mon–Fri | B7: Lunch | C7: HLD read, 25–30 min | D7: The day's office topic; read or watch
A8: Mon–Fri | B8: 7:00 pm | C8: Home, shower, dinner | D8: Second litre done by now
A9: Mon–Fri | B9: 8:00 pm | C9: Free time | D9: Guilt-free, at least 1 hour
A10: Mon–Fri | B10: 9:00 pm | C10: LLD 30 min + cloud 30 min, then LeetCode #3 | D10: Code the LLD in C#, then the cloud lab
A11: Mon–Fri | B11: 10:15 pm | C11: Wind down | D11: Screens down by 11
A12: Mon–Fri | B12: 11:15 pm | C12: Sleep | D12: Protect ~7.5 hours
... A15: Saturday | B15: Afternoon | C15: Clean up cloud resources | D15: Check the billing alarm
A16: Saturday | B16: Rest | C16: Free
A17: Sunday | B17: Morning | C17: Easy 1 km walk + 3 LeetCode | D17: Re-solve every ↻ revisit from the week first
A18: Sunday | B18: Midday | C18: 45 min: revise the week on one page | D18: Say each topic out loud in 2 sentences
A19: Sunday | B19: Evening | C19: Meal prep for the week | D19: Plan Monday's first problem
A20: Sunday | B20: Rest | C20: Free
A22: Rules
C23: 3 LeetCode a day: 2 in the morning, 1 at night. 30 minutes max per problem; if stuck, read the solution, mark it ↻ revisit and re-solve it on Sunday.
C24: Floor vs full: on a drained day switch to Easy day - 3 easy LeetCode + 1 km walk + water + clean food + the HLD read still counts.
C25: One theme a day: the HLD read, the LLD code and the cloud lab explain the same idea from three angles.
C26: One cloud at a time: AWS for days 1–50, Azure for 51–75, each mapped to the AWS service you already know.
C27: Cloud labs: always delete resources afterwards and keep a billing alarm on.
C28: Never double up to catch up: missed tasks go to the catch-up list and get done on Saturday or Sunday.
C29: Checkpoints on days 25, 50 and 75 have pass criteria - if one fails, repeat its weak topic before moving on.
A30: Easy day | C30: 3 LeetCode (the day's easiest, or Easy re-solves) · Walk 1 km · Water 2.5 L · Clean food · HLD read only
